Workbook

Sheet Reporte a FCCF
B2: Club: | C2: Vélez | G2: Torneo: | I2: Apertura 2026 | P2: Fecha:
B4: Rival: | C4: Avellaneda | G4: Categoría: | I4: Primera A
D6: 1er tiempo | L6: 2do tiempo | T6: 1er tiempo suplementario | AB6: 2do tiempo suplementario | AJ6: TOTAL
B7: # | C7: Nombre | D7: Lanza mientos | E7: Goles | G7: Rebotes | I7: Recu peros | J7: Pér didas | K7: Faltas | L7: Lanza mientos | M7: Goles | O7: Rebotes | Q7: Recu peros | R7: Pér didas | S7: Faltas | T7: Lanza mientos | U7: Goles | W7: Rebotes | Y7: Recu peros | Z7: Pér didas | AA7: Faltas | AB7: Lanza mientos | AC7: Goles | AE7: Rebotes | AG7: Recu peros | AH7: Pér didas | AI7: Faltas | AJ7: Lanza mientos | AK7: Goles | AM7: Rebotes | AO7: Recuperos | AP7: Pérdidas | AQ7: Faltas
E8: Dobles | F8: Triples | G8: Ofens | H8: Defens | M8: Dobles | N8: Triples | O8: Ofens | P8: Defens | U8: Dobles | V8: Triples | W8: Ofens | X8: Defens | AC8: Dobles | AD8: Triples | AE8: Ofens | AF8: Defens | AK8: Dobles | AL8: Triples | AM8: Ofensivos | AN8: Defensivos
B9: 1 | C9: LUCIA COSTA | D9: 4 | E9: 1 | F9: 0 | G9: 2 | H9: 1 | I9: 0 | J9: 2 | K9: 1 | L9: 0 | M9: 0 | N9: 0 | O9: 1 | P9: 0 | Q9: 0 | R9: 1 | S9: 5 | AJ9: =+D9+L9+T9+AB9 -> 4 | AK9: =+E9+M9+U9+AC9 -> 1 | AL9: =+F9+N9+V9+AD9 -> 0 | AM9: =+G9+O9+W9+AE9 -> 3 | AN9: =+H9+P9+X9+AF9 -> 1 | AO9: =+I9+Q9+Y9+AG9 -> 0 | AP9: =+J9+R9+Z9+AH9 -> 3 | AQ9: =+K9+S9+AA9+AI9 -> 6
B10: 5 | C10: MARIELA ELIAS | D10: 0 | E10: 0 | F10: 0 | G10: 0 | H10: 0 | I10: 0 | J10: 0 | K10: 0 | L10: 1 | M10: 0 | N10: 0 | O10: 0 | P10: 3 | Q10: 2 | R10: 4 | S10: 5 | AJ10: =+D10+L10+T10+AB10 -> 1 | AK10: =+E10+M10+U10+AC10 -> 0 | AL10: =+F10+N10+V10+AD10 -> 0 | AM10: =+G10+O10+W10+AE10 -> 0 | AN10: =+H10+P10+X10+AF10 -> 3 | AO10: =+I10+Q10+Y10+AG10 -> 2 | AP10: =+J10+R10+Z10+AH10 -> 4 | AQ10: =+K10+S10+AA10+AI10 -> 5
B11: 6 | C11: MALENA ZUCCARINO | D11: 0 | E11: 0 | F11: 0 | G11: 0 | H11: 0 | I11: 0 | J11: 0 | K11: 0 | L11: 4 | M11: 2 | N11: 0 | O11: 2 | P11: 1 | Q11: 0 | R11: 0 | S11: 3 | AJ11: =+D11+L11+T11+AB11 -> 4 | AK11: =+E11+M11+U11+AC11 -> 2 | AL11: =+F11+N11+V11+AD11 -> 0 | AM11: =+G11+O11+W11+AE11 -> 2 | AN11: =+H11+P11+X11+AF11 -> 1 | AO11: =+I11+Q11+Y11+AG11 -> 0 | AP11: =+J11+R11+Z11+AH11 -> 0 | AQ11: =+K11+S11+AA11+AI11 -> 3
B12: 7 | C12: JIMENA GARCIA | D12: 11 | E12: 5 | F12: 0 | G12: 0 | H12: 0 | I12: 1 | J12: 2 | K12: 2 | L12: 9 | M12: 4 | N12: 0 | O12: 1 | P12: 0 | Q12: 0 | R12: 1 | S12: 1 | AJ12: =+D12+L12+T12+AB12 -> 20 | AK12: =+E12+M12+U12+AC12 -> 9 | AL12: =+F12+N12+V12+AD12 -> 0 | AM12: =+G12+O12+W12+AE12 -> 1 | AN12: =+H12+P12+X12+AF12 -> 0 | AO12: =+I12+Q12+Y12+AG12 -> 1 | AP12: =+J12+R12+Z12+AH12 -> 3 | AQ12: =+K12+S12+AA12+AI12 -> 3
B13: 8 | C13: SOFIA NAÓN | D13: 6 | E13: 3 | F13: 0 | G13: 0 | H13: 3 | I13: 0 | J13: 3 | K13: 2 | L13: 8 | M13: 5 | N13: 0 | O13: 2 | P13: 0 | Q13: 1 | R13: 0 | S13: 3 | AJ13: =+D13+L13+T13+AB13 -> 14 | AK13: =+E13+M13+U13+AC13 -> 8 | AL13: =+F13+N13+V13+AD13 -> 0 | AM13: =+G13+O13+W13+AE13 -> 2 | AN13: =+H13+P13+X13+AF13 -> 3 | AO13: =+I13+Q13+Y13+AG13 -> 1 | AP13: =+J13+R13+Z13+AH13 -> 3 | AQ13: =+K13+S13+AA13+AI13 -> 5
B14: 9 | C14: VICTORIA FONTAN | D14: 1 | E14: 0 | F14: 0 | G14: 0 | H14: 7 | I14: 2 | J14: 1 | K14: 3 | L14: 4 | M14: 2 | N14: 0 | O14: 0 | P14: 10 | Q14: 0 | R14: 0 | S14: 1 | AJ14: =+D14+L14+T14+AB14 -> 5 | AK14: =+E14+M14+U14+AC14 -> 2 | AL14: =+F14+N14+V14+AD14 -> 0 | AM14: =+G14+O14+W14+AE14 -> 0 | AN14: =+H14+P14+X14+AF14 -> 17 | AO14: =+I14+Q14+Y14+AG14 -> 2 | AP14: =+J14+R14+Z14+AH14 -> 1 | AQ14: =+K14+S14+AA14+AI14 -> 4
B15: 10 | C15: ZAHIRA HERRERA | D15: 0 | E15: 0 | F15: 0 | G15: 0 | H15: 1 | I15: 0 | J15: 1 | K15: 3 | L15: 0 | M15: 0 | N15: 0 | O15: 0 | P15: 0 | Q15: 1 | R15: 0 | S15: 3 | AJ15: =+D15+L15+T15+AB15 -> 0 | AK15: =+E15+M15+U15+AC15 -> 0 | AL15: =+F15+N15+V15+AD15 -> 0 | AM15: =+G15+O15+W15+AE15 -> 0 | AN15: =+H15+P15+X15+AF15 -> 1 | AO15: =+I15+Q15+Y15+AG15 -> 1 | AP15: =+J15+R15+Z15+AH15 -> 1 | AQ15: =+K15+S15+AA15+AI15 -> 6
B16: 11 | C16: LUCILA GRANATELLI | D16: 9 | E16: 6 | F16: 0 | G16: 1 | H16: 1 | I16: 0 | J16: 0 | K16: 4 | L16: 7 | M16: 5 | N16: 0 | O16: 2 | P16: 0 | Q16: 0 | R16: 1 | S16: 0 | AJ16: =+D16+L16+T16+AB16 -> 16 | AK16: =+E16+M16+U16+AC16 -> 11 | AL16: =+F16+N16+V16+AD16 -> 0 | AM16: =+G16+O16+W16+AE16 -> 3 | AN16: =+H16+P16+X16+AF16 -> 1 | AO16: =+I16+Q16+Y16+AG16 -> 0 | AP16: =+J16+R16+Z16+AH16 -> 1 | AQ16: =+K16+S16+AA16+AI16 -> 4
B17: 12 | C17: MARIA PAZ GOMEZ | D17: 1 | E17: 0 | F17: 0 | G17: 0 | H17: 0 | I17: 1 | J17: 0 | K17: 0 | L17: 10 | M17: 5 | N17: 2 | O17: 1 | P17: 1 | Q17: 0 | R17: 1 | S17: 1 | AJ17: =+D17+L17+T17+AB17 -> 11 | AK17: =+E17+M17+U17+AC17 -> 5 | AL17: =+F17+N17+V17+AD17 -> 2 | AM17: =+G17+O17+W17+AE17 -> 1 | AN17: =+H17+P17+X17+AF17 -> 1 | AO17: =+I17+Q17+Y17+AG17 -> 1 | AP17: =+J17+R17+Z17+AH17 -> 1 | AQ17: =+K17+S17+AA17+AI17 -> 1
B18: 14 | C18: LUCIANA BRINGAS | D18: 0 | E18: 0 | F18: 0 | G18: 0 | H18: 1 | I18: 0 | J18: 0 | K18: 1 | L18: 1 | M18: 0 | N18: 0 | O18: 0 | P18: 1 | Q18: 1 | R18: 0 | S18: 4 | AJ18: =+D18+L18+T18+AB18 -> 1 | AK18: =+E18+M18+U18+AC18 -> 0 | AL18: =+F18+N18+V18+AD18 -> 0 | AM18: =+G18+O18+W18+AE18 -> 0 | AN18: =+H18+P18+X18+AF18 -> 2 | AO18: =+I18+Q18+Y18+AG18 -> 1 | AP18: =+J18+R18+Z18+AH18 -> 0 | AQ18: =+K18+S18+AA18+AI18 -> 5
B19: 15 | C19: CANDELA THIM | D19: 4 | E19: 1 | F19: 0 | G19: 1 | H19: 0 | I19: 0 | J19: 1 | K19: 2 | L19: 0 | M19: 0 | N19: 0 | O19: 0 | P19: 0 | Q19: 0 | R19: 0 | S19: 0 | AJ19: =+D19+L19+T19+AB19 -> 4 | AK19: =+E19+M19+U19+AC19 -> 1 | AL19: =+F19+N19+V19+AD19 -> 0 | AM19: =+G19+O19+W19+AE19 -> 1 | AN19: =+H19+P19+X19+AF19 -> 0 | AO19: =+I19+Q19+Y19+AG19 -> 0 | AP19: =+J19+R19+Z19+AH19 -> 1 | AQ19: =+K19+S19+AA19+AI19 -> 2
AJ20: =+D20+L20+T20+AB20 -> 0 | AK20: =+E20+M20+U20+AC20 -> 0 | AL20: =+F20+N20+V20+AD20 -> 0 | AM20: =+G20+O20+W20+AE20 -> 0 | AN20: =+H20+P20+X20+AF20 -> 0 | AO20: =+I20+Q20+Y20+AG20 -> 0 | AP20: =+J20+R20+Z20+AH20 -> 0 | AQ20: =+K20+S20+AA20+AI20 -> 0
B22: TOTAL | D22: =SUM(D9:D20) -> 36 | E22: =SUM(E9:E20) -> 16 | F22: =SUM(F9:F20) -> 0 | G22: =SUM(G9:G20) -> 4 | H22: =SUM(H9:H20) -> 14 | I22: =SUM(I9:I20) -> 4 | J22: =SUM(J9:J20) -> 10 | K22: =SUM(K9:K20) -> 18 | ... AQ22: =SUM(AQ9:AQ20) -> 44
B24: Estadísticas | Reporte a FCCF v2

Sheet Crudo
A1: Categoría | B1: Torneo | C1: Fecha | D1: Club | E1: Rival | F1: Tiempo | G1: # jugador | H1: Nombre jugador | I1: Lanza mientos | J1: Dobles | K1: Triples | L1: Ofens | M1: Defens | N1: Recu peros | O1: Pér didas | P1: Faltas
A2: =+'Reporte a FCCF'!$I$4 -> Primera A | B2: =+'Reporte a FCCF'!$I$2 -> Apertura 2026 | C2: =+'Reporte a FCCF'!$Q$2 -> 0 | D2: =+'Reporte a FCCF'!$C$2 -> Vélez | E2: =+'Reporte a FCCF'!$C$4 -> Avellaneda | F2: 1er tiempo | G2: =+'Reporte a FCCF'!$B$9 -> 1 | H2: =+'Reporte a FCCF'!$C$9 -> LUCIA COSTA | I2: =+'Reporte a FCCF'!D9 -> 4 | J2: =+'Reporte a FCCF'!E9 -> 1 | K2: =+'Reporte a FCCF'!F9 -> 0 | L2: =+'Reporte a FCCF'!G9 -> 2 | M2: =+'Reporte a FCCF'!H9 -> 1 | N2: =+'Reporte a FCCF'!I9 -> 0 | O2: =+'Reporte a FCCF'!J9 -> 2 | P2: =+'Reporte a FCCF'!K9 -> 1
A3: =+'Reporte a FCCF'!$I$4 -> Primera A | B3: =+'Reporte a FCCF'!$I$2 -> Apertura 2026 | C3: =+'Reporte a FCCF'!$Q$2 -> 0 | D3: =+'Reporte a FCCF'!$C$2 -> Vélez | E3: =+'Reporte a FCCF'!$C$4 -> Avellaneda | F3: 1er tiempo | G3: =+'Reporte a FCCF'!$B$10 -> 5 | H3: =+'Reporte a FCCF'!$C$10 -> MARIELA ELIAS | I3: =+'Reporte a FCCF'!D10 -> 0 | J3: =+'Reporte a FCCF'!E10 -> 0 | K3: =+'Reporte a FCCF'!F10 -> 0 | L3: =+'Reporte a FCCF'!G10 -> 0 | M3: =+'Reporte a FCCF'!H10 -> 0 | N3: =+'Reporte a FCCF'!I10 -> 0 | O3: =+'Reporte a FCCF'!J10 -> 0 | P3: =+'Reporte a FCCF'!K10 -> 0
A4: =+'Reporte a FCCF'!$I$4 -> Primera A | B4: =+'Reporte a FCCF'!$I$2 -> Apertura 2026 | C4: =+'Reporte a FCCF'!$Q$2 -> 0 | D4: =+'Reporte a FCCF'!$C$2 -> Vélez | E4: =+'Reporte a FCCF'!$C$4 -> Avellaneda | F4: 1er tiempo | G4: =+'Reporte a FCCF'!$B$11 -> 6 | H4: =+'Reporte a FCCF'!$C$11 -> MALENA ZUCCARINO | I4: =+'Reporte a FCCF'!D11 -> 0 | J4: =+'Reporte a FCCF'!E11 -> 0 | K4: =+'Reporte a FCCF'!F11 -> 0 | L4: =+'Reporte a FCCF'!G11 -> 0 | M4: =+'Reporte a FCCF'!H11 -> 0 | N4: =+'Reporte a FCCF'!I11 -> 0 | O4: =+'Reporte a FCCF'!J11 -> 0 | P4: =+'Reporte a FCCF'!K11 -> 0
A5: =+'Reporte a FCCF'!$I$4 -> Primera A | B5: =+'Reporte a FCCF'!$I$2 -> Apertura 2026 | C5: =+'Reporte a FCCF'!$Q$2 -> 0 | D5: =+'Reporte a FCCF'!$C$2 -> Vélez | E5: =+'Reporte a FCCF'!$C$4 -> Avellaneda | F5: 1er tiempo | G5: =+'Reporte a FCCF'!$B$12 -> 7 | H5: =+'Reporte a FCCF'!$C$12 -> JIMENA GARCIA | I5: =+'Reporte a FCCF'!D12 -> 11 | J5: =+'Reporte a FCCF'!E12 -> 5 | K5: =+'Reporte a FCCF'!F12 -> 0 | L5: =+'Reporte a FCCF'!G12 -> 0 | M5: =+'Reporte a FCCF'!H12 -> 0 | N5: =+'Reporte a FCCF'!I12 -> 1 | O5: =+'Reporte a FCCF'!J12 -> 2 | P5: =+'Reporte a FCCF'!K12 -> 2
A6: =+'Reporte a FCCF'!$I$4 -> Primera A | B6: =+'Reporte a FCCF'!$I$2 -> Apertura 2026 | C6: =+'Reporte a FCCF'!$Q$2 -> 0 | D6: =+'Reporte a FCCF'!$C$2 -> Vélez | E6: =+'Reporte a FCCF'!$C$4 -> Avellaneda | F6: 1er tiempo | G6: =+'Reporte a FCCF'!$B$13 -> 8 | H6: =+'Reporte a FCCF'!$C$13 -> SOFIA NAÓN | I6: =+'Reporte a FCCF'!D13 -> 6 | J6: =+'Reporte a FCCF'!E13 -> 3 | K6: =+'Reporte a FCCF'!F13 -> 0 | L6: =+'Reporte a FCCF'!G13 -> 0 | M6: =+'Reporte a FCCF'!H13 -> 3 | N6: =+'Reporte a FCCF'!I13 -> 0 | O6: =+'Reporte a FCCF'!J13 -> 3 | P6: =+'Reporte a FCCF'!K13 -> 2
A7: =+'Reporte a FCCF'!$I$4 -> Primera A | B7: =+'Reporte a FCCF'!$I$2 -> Apertura 2026 | C7: =+'Reporte a FCCF'!$Q$2 -> 0 | D7: =+'Reporte a FCCF'!$C$2 -> Vélez | E7: =+'Reporte a FCCF'!$C$4 -> Avellaneda | F7: 1er tiempo | G7: =+'Reporte a FCCF'!$B$14 -> 9 | H7: =+'Reporte a FCCF'!$C$14 -> VICTORIA FONTAN | I7: =+'Reporte a FCCF'!D14 -> 1 | J7: =+'Reporte a FCCF'!E14 -> 0 | K7: =+'Reporte a FCCF'!F14 -> 0 | L7: =+'Reporte a FCCF'!G14 -> 0 | M7: =+'Reporte a FCCF'!H14 -> 7 | N7: =+'Reporte a FCCF'!I14 -> 2 | O7: =+'Reporte a FCCF'!J14 -> 1 | P7: =+'Reporte a FCCF'!K14 -> 3
A8: =+'Reporte a FCCF'!$I$4 -> Primera A | B8: =+'Reporte a FCCF'!$I$2 -> Apertura 2026 | C8: =+'Reporte a FCCF'!$Q$2 -> 0 | D8: =+'Reporte a FCCF'!$C$2 -> Vélez | E8: =+'Reporte a FCCF'!$C$4 -> Avellaneda | F8: 1er tiempo | G8: =+'Reporte a FCCF'!$B$15 -> 10 | H8: =+'Reporte a FCCF'!$C$15 -> ZAHIRA HERRERA | I8: =+'Reporte a FCCF'!D15 -> 0 | J8: =+'Reporte a FCCF'!E15 -> 0 | K8: =+'Reporte a FCCF'!F15 -> 0 | L8: =+'Reporte a FCCF'!G15 -> 0 | M8: =+'Reporte a FCCF'!H15 -> 1 | N8: =+'Reporte a FCCF'!I15 -> 0 | O8: =+'Reporte a FCCF'!J15 -> 1 | P8: =+'Reporte a FCCF'!K15 -> 3
A9: =+'Reporte a FCCF'!$I$4 -> Primera A | B9: =+'Reporte a FCCF'!$I$2 -> Apertura 2026 | C9: =+'Reporte a FCCF'!$Q$2 -> 0 | D9: =+'Reporte a FCCF'!$C$2 -> Vélez | E9: =+'Reporte a FCCF'!$C$4 -> Avellaneda | F9: 1er tiempo | G9: =+'Reporte a FCCF'!$B$16 -> 11 | H9: =+'Reporte a FCCF'!$C$16 -> LUCILA GRANATELLI | I9: =+'Reporte a FCCF'!D16 -> 9 | J9: =+'Reporte a FCCF'!E16 -> 6 | K9: =+'Reporte a FCCF'!F16 -> 0 | L9: =+'Reporte a FCCF'!G16 -> 1 | M9: =+'Reporte a FCCF'!H16 -> 1 | N9: =+'Reporte a FCCF'!I16 -> 0 | O9: =+'Reporte a FCCF'!J16 -> 0 | P9: =+'Reporte a FCCF'!K16 -> 4
A10: =+'Reporte a FCCF'!$I$4 -> Primera A | B10: =+'Reporte a FCCF'!$I$2 -> Apertura 2026 | C10: =+'Reporte a FCCF'!$Q$2 -> 0 | D10: =+'Reporte a FCCF'!$C$2 -> Vélez | E10: =+'Reporte a FCCF'!$C$4 -> Avellaneda | F10: 1er tiempo | G10: =+'Reporte a FCCF'!$B$17 -> 12 | H10: =+'Reporte a FCCF'!$C$17 -> MARIA PAZ GOMEZ | I10: =+'Reporte a FCCF'!D17 -> 1 | J10: =+'Reporte a FCCF'!E17 -> 0 | K10: =+'Reporte a FCCF'!F17 -> 0 | L10: =+'Reporte a FCCF'!G17 -> 0 | M10: =+'Reporte a FCCF'!H17 -> 0 | N10: =+'Reporte a FCCF'!I17 -> 1 | O10: =+'Reporte a FCCF'!J17 -> 0 | P10: =+'Reporte a FCCF'!K17 -> 0
A11: =+'Reporte a FCCF'!$I$4 -> Primera A | B11: =+'Reporte a FCCF'!$I$2 -> Apertura 2026 | C11: =+'Reporte a FCCF'!$Q$2 -> 0 | D11: =+'Reporte a FCCF'!$C$2 -> Vélez | E11: =+'Reporte a FCCF'!$C$4 -> Avellaneda | F11: 1er tiempo | G11: =+'Reporte a FCCF'!$B$18 -> 14 | H11: =+'Reporte a FCCF'!$C$18 -> LUCIANA BRINGAS | I11: =+'Reporte a FCCF'!D18 -> 0 | J11: =+'Reporte a FCCF'!E18 -> 0 | K11: =+'Reporte a FCCF'!F18 -> 0 | L11: =+'Reporte a FCCF'!G18 -> 0 | M11: =+'Reporte a FCCF'!H18 -> 1 | N11: =+'Reporte a FCCF'!I18 -> 0 | O11: =+'Reporte a FCCF'!J18 -> 0 | P11: =+'Reporte a FCCF'!K18 -> 1
A12: =+'Reporte a FCCF'!$I$4 -> Primera A | B12: =+'Reporte a FCCF'!$I$2 -> Apertura 2026 | C12: =+'Reporte a FCCF'!$Q$2 -> 0 | D12: =+'Reporte a FCCF'!$C$2 -> Vélez | E12: =+'Reporte a FCCF'!$C$4 -> Avellaneda | F12: 1er tiempo | G12: =+'Reporte a FCCF'!$B$19 -> 15 | H12: =+'Reporte a FCCF'!$C$19 -> CANDELA THIM | I12: =+'Reporte a FCCF'!D19 -> 4 | J12: =+'Reporte a FCCF'!E19 -> 1 | K12: =+'Reporte a FCCF'!F19 -> 0 | L12: =+'Reporte a FCCF'!G19 -> 1 | M12: =+'Reporte a FCCF'!H19 -> 0 | N12: =+'Reporte a FCCF'!I19 -> 0 | O12: =+'Reporte a FCCF'!J19 -> 1 | P12: =+'Reporte a FCCF'!K19 -> 2
A13: =+'Reporte a FCCF'!$I$4 -> Primera A | B13: =+'Reporte a FCCF'!$I$2 -> Apertura 2026 | C13: =+'Reporte a FCCF'!$Q$2 -> 0 | D13: =+'Reporte a FCCF'!$C$2 -> Vélez | E13: =+'Reporte a FCCF'!$C$4 -> Avellaneda | F13: 1er tiempo | G13: =+'Reporte a FCCF'!$B$20 -> 0 | H13: =+'Reporte a FCCF'!$C$20 -> 0 | I13: =+'Reporte a FCCF'!D20 -> 0 | J13: =+'Reporte a FCCF'!E20 -> 0 | K13: =+'Reporte a FCCF'!F20 -> 0 | L13: =+'Reporte a FCCF'!G20 -> 0 | M13: =+'Reporte a FCCF'!H20 -> 0 | N13: =+'Reporte a FCCF'!I20 -> 0 | O13: =+'Reporte a FCCF'!J20 -> 0 | P13: =+'Reporte a FCCF'!K20 -> 0
A14: =+'Reporte a FCCF'!$I$4 -> Primera A | B14: =+'Reporte a FCCF'!$I$2 -> Apertura 2026 | C14: =+'Reporte a FCCF'!$Q$2 -> 0 | D14: =+'Reporte a FCCF'!$C$2 -> Vélez | E14: =+'Reporte a FCCF'!$C$4 -> Avellaneda | F14: 2do tiempo | G14: =+'Reporte a FCCF'!$B$9 -> 1 | H14: =+'Reporte a FCCF'!$C$9 -> LUCIA COSTA | I14: =+'Reporte a FCCF'!L9 -> 0 | J14: =+'Reporte a FCCF'!M9 -> 0 | K14: =+'Reporte a FCCF'!N9 -> 0 | L14: =+'Reporte a FCCF'!O9 -> 1 | M14: =+'Reporte a FCCF'!P9 -> 0 | N14: =+'Reporte a FCCF'!Q9 -> 0 | O14: =+'Reporte a FCCF'!R9 -> 1 | P14: =+'Reporte a FCCF'!S9 -> 5
A15: =+'Reporte a FCCF'!$I$4 -> Primera A | B15: =+'Reporte a FCCF'!$I$2 -> Apertura 2026 | C15: =+'Reporte a FCCF'!$Q$2 -> 0 | D15: =+'Reporte a FCCF'!$C$2 -> Vélez | E15: =+'Reporte a FCCF'!$C$4 -> Avellaneda | F15: 2do tiempo | G15: =+'Reporte a FCCF'!$B$10 -> 5 | H15: =+'Reporte a FCCF'!$C$10 -> MARIELA ELIAS | I15: =+'Reporte a FCCF'!L10 -> 1 | J15: =+'Reporte a FCCF'!M10 -> 0 | K15: =+'Reporte a FCCF'!N10 -> 0 | L15: =+'Reporte a FCCF'!O10 -> 0 | M15: =+'Reporte a FCCF'!P10 -> 3 | N15: =+'Reporte a FCCF'!Q10 -> 2 | O15: =+'Reporte a FCCF'!R10 -> 4 | P15: =+'Reporte a FCCF'!S10 -> 5
A16: =+'Reporte a FCCF'!$I$4 -> Primera A | B16: =+'Reporte a FCCF'!$I$2 -> Apertura 2026 | C16: =+'Reporte a FCCF'!$Q$2 -> 0 | D16: =+'Reporte a FCCF'!$C$2 -> Vélez | E16: =+'Reporte a FCCF'!$C$4 -> Avellaneda | F16: 2do tiempo | G16: =+'Reporte a FCCF'!$B$11 -> 6 | H16: =+'Reporte a FCCF'!$C$11 -> MALENA ZUCCARINO | I16: =+'Reporte a FCCF'!L11 -> 4 | J16: =+'Reporte a FCCF'!M11 -> 2 | K16: =+'Reporte a FCCF'!N11 -> 0 | L16: =+'Reporte a FCCF'!O11 -> 2 | M16: =+'Reporte a FCCF'!P11 -> 1 | N16: =+'Reporte a FCCF'!Q11 -> 0 | O16: =+'Reporte a FCCF'!R11 -> 0 | P16: =+'Reporte a FCCF'!S11 -> 3
A17: =+'Reporte a FCCF'!$I$4 -> Primera A | B17: =+'Reporte a FCCF'!$I$2 -> Apertura 2026 | C17: =+'Reporte a FCCF'!$Q$2 -> 0 | D17: =+'Reporte a FCCF'!$C$2 -> Vélez | E17: =+'Reporte a FCCF'!$C$4 -> Avellaneda | F17: 2do tiempo | G17: =+'Reporte a FCCF'!$B$12 -> 7 | H17: =+'Reporte a FCCF'!$C$12 -> JIMENA GARCIA | I17: =+'Reporte a FCCF'!L12 -> 9 | J17: =+'Reporte a FCCF'!M12 -> 4 | K17: =+'Reporte a FCCF'!N12 -> 0 | L17: =+'Reporte a FCCF'!O12 -> 1 | M17: =+'Reporte a FCCF'!P12 -> 0 | N17: =+'Reporte a FCCF'!Q12 -> 0 | O17: =+'Reporte a FCCF'!R12 -> 1 | P17: =+'Reporte a FCCF'!S12 -> 1
A18: =+'Reporte a FCCF'!$I$4 -> Primera A | B18: =+'Reporte a FCCF'!$I$2 -> Apertura 2026 | C18: =+'Reporte a FCCF'!$Q$2 -> 0 | D18: =+'Reporte a FCCF'!$C$2 -> Vélez | E18: =+'Reporte a FCCF'!$C$4 -> Avellaneda | F18: 2do tiempo | G18: =+'Reporte a FCCF'!$B$13 -> 8 | H18: =+'Reporte a FCCF'!$C$13 -> SOFIA NAÓN | I18: =+'Reporte a FCCF'!L13 -> 8 | J18: =+'Reporte a FCCF'!M13 -> 5 | K18: =+'Reporte a FCCF'!N13 -> 0 | L18: =+'Reporte a FCCF'!O13 -> 2 | M18: =+'Reporte a FCCF'!P13 -> 0 | N18: =+'Reporte a FCCF'!Q13 -> 1 | O18: =+'Reporte a FCCF'!R13 -> 0 | P18: =+'Reporte a FCCF'!S13 -> 3
A19: =+'Reporte a FCCF'!$I$4 -> Primera A | B19: =+'Reporte a FCCF'!$I$2 -> Apertura 2026 | C19: =+'Reporte a FCCF'!$Q$2 -> 0 | D19: =+'Reporte a FCCF'!$C$2 -> Vélez | E19: =+'Reporte a FCCF'!$C$4 -> Avellaneda | F19: 2do tiempo | G19: =+'Reporte a FCCF'!$B$14 -> 9 | H19: =+'Reporte a FCCF'!$C$14 -> VICTORIA FONTAN | I19: =+'Reporte a FCCF'!L14 -> 4 | J19: =+'Reporte a FCCF'!M14 -> 2 | K19: =+'Reporte a FCCF'!N14 -> 0 | L19: =+'Reporte a FCCF'!O14 -> 0 | M19: =+'Reporte a FCCF'!P14 -> 10 | N19: =+'Reporte a FCCF'!Q14 -> 0 | O19: =+'Reporte a FCCF'!R14 -> 0 | P19: =+'Reporte a FCCF'!S14 -> 1
A20: =+'Reporte a FCCF'!$I$4 -> Primera A | B20: =+'Reporte a FCCF'!$I$2 -> Apertura 2026 | C20: =+'Reporte a FCCF'!$Q$2 -> 0 | D20: =+'Reporte a FCCF'!$C$2 -> Vélez | E20: =+'Reporte a FCCF'!$C$4 -> Avellaneda | F20: 2do tiempo | G20: =+'Reporte a FCCF'!$B$15 -> 10 | H20: =+'Reporte a FCCF'!$C$15 -> ZAHIRA HERRERA | I20: =+'Reporte a FCCF'!L15 -> 0 | J20: =+'Reporte a FCCF'!M15 -> 0 | K20: =+'Reporte a FCCF'!N15 -> 0 | L20: =+'Reporte a FCCF'!O15 -> 0 | M20: =+'Reporte a FCCF'!P15 -> 0 | N20: =+'Reporte a FCCF'!Q15 -> 1 | O20: =+'Reporte a FCCF'!R15 -> 0 | P20: =+'Reporte a FCCF'!S15 -> 3
A21: =+'Reporte a FCCF'!$I$4 -> Primera A | B21: =+'Reporte a FCCF'!$I$2 -> Apertura 2026 | C21: =+'Reporte a FCCF'!$Q$2 -> 0 | D21: =+'Reporte a FCCF'!$C$2 -> Vélez | E21: =+'Reporte a FCCF'!$C$4 -> Avellaneda | F21: 2do tiempo | G21: =+'Reporte a FCCF'!$B$16 -> 11 | H21: =+'Reporte a FCCF'!$C$16 -> LUCILA GRANATELLI | I21: =+'Reporte a FCCF'!L16 -> 7 | J21: =+'Reporte a FCCF'!M16 -> 5 | K21: =+'Reporte a FCCF'!N16 -> 0 | L21: =+'Reporte a FCCF'!O16 -> 2 | M21: =+'Reporte a FCCF'!P16 -> 0 | N21: =+'Reporte a FCCF'!Q16 -> 0 | O21: =+'Reporte a FCCF'!R16 -> 1 | P21: =+'Reporte a FCCF'!S16 -> 0
A22: =+'Reporte a FCCF'!$I$4 -> Primera A | B22: =+'Reporte a FCCF'!$I$2 -> Apertura 2026 | C22: =+'Reporte a FCCF'!$Q$2 -> 0 | D22: =+'Reporte a FCCF'!$C$2 -> Vélez | E22: =+'Reporte a FCCF'!$C$4 -> Avellaneda | F22: 2do tiempo | G22: =+'Reporte a FCCF'!$B$17 -> 12 | H22: =+'Reporte a FCCF'!$C$17 -> MARIA PAZ GOMEZ | I22: =+'Reporte a FCCF'!L17 -> 10 | J22: =+'Reporte a FCCF'!M17 -> 5 | K22: =+'Reporte a FCCF'!N17 -> 2 | L22: =+'Reporte a FCCF'!O17 -> 1 | M22: =+'Reporte a FCCF'!P17 -> 1 | N22: =+'Reporte a FCCF'!Q17 -> 0 | O22: =+'Reporte a FCCF'!R17 -> 1 | P22: =+'Reporte a FCCF'!S17 -> 1
A23: =+'Reporte a FCCF'!$I$4 -> Primera A | B23: =+'Reporte a FCCF'!$I$2 -> Apertura 2026 | C23: =+'Reporte a FCCF'!$Q$2 -> 0 | D23: =+'Reporte a FCCF'!$C$2 -> Vélez | E23: =+'Reporte a FCCF'!$C$4 -> Avellaneda | F23: 2do tiempo | G23: =+'Reporte a FCCF'!$B$18 -> 14 | H23: =+'Reporte a FCCF'!$C$18 -> LUCIANA BRINGAS | I23: =+'Reporte a FCCF'!L18 -> 1 | J23: =+'Reporte a FCCF'!M18 -> 0 | K23: =+'Reporte a FCCF'!N18 -> 0 | L23: =+'Reporte a FCCF'!O18 -> 0 | M23: =+'Reporte a FCCF'!P18 -> 1 | N23: =+'Reporte a FCCF'!Q18 -> 1 | O23: =+'Reporte a FCCF'!R18 -> 0 | P23: =+'Reporte a FCCF'!S18 -> 4
A24: =+'Reporte a FCCF'!$I$4 -> Primera A | B24: =+'Reporte a FCCF'!$I$2 -> Apertura 2026 | C24: =+'Reporte a FCCF'!$Q$2 -> 0 | D24: =+'Reporte a FCCF'!$C$2 -> Vélez | E24: =+'Reporte a FCCF'!$C$4 -> Avellaneda | F24: 2do tiempo | G24: =+'Reporte a FCCF'!$B$19 -> 15 | H24: =+'Reporte a FCCF'!$C$19 -> CANDELA THIM | I24: =+'Reporte a FCCF'!L19 -> 0 | J24: =+'Reporte a FCCF'!M19 -> 0 | K24: =+'Reporte a FCCF'!N19 -> 0 | L24: =+'Reporte a FCCF'!O19 -> 0 | M24: =+'Reporte a FCCF'!P19 -> 0 | N24: =+'Reporte a FCCF'!Q19 -> 0 | O24: =+'Reporte a FCCF'!R19 -> 0 | P24: =+'Reporte a FCCF'!S19 -> 0
A25: =+'Reporte a FCCF'!$I$4 -> Primera A | B25: =+'Reporte a FCCF'!$I$2 -> Apertura 2026 | C25: =+'Reporte a FCCF'!$Q$2 -> 0 | D25: =+'Reporte a FCCF'!$C$2 -> Vélez | E25: =+'Reporte a FCCF'!$C$4 -> Avellaneda | F25: 2do tiempo | G25: =+'Reporte a FCCF'!$B$20 -> 0 | H25: =+'Reporte a FCCF'!$C$20 -> 0 | I25: =+'Reporte a FCCF'!L20 -> 0 | J25: =+'Reporte a FCCF'!M20 -> 0 | K25: =+'Reporte a FCCF'!N20 -> 0 | L25: =+'Reporte a FCCF'!O20 -> 0 | M25: =+'Reporte a FCCF'!P20 -> 0 | N25: =+'Reporte a FCCF'!Q20 -> 0 | O25: =+'Reporte a FCCF'!R20 -> 0 | P25: =+'Reporte a FCCF'!S20 -> 0
A26: =+'Reporte a FCCF'!$I$4 -> Primera A | B26: =+'Reporte a FCCF'!$I$2 -> Apertura 2026 | C26: =+'Reporte a FCCF'!$Q$2 -> 0 | D26: =+'Reporte a FCCF'!$C$2 -> Vélez | E26: =+'Reporte a FCCF'!$C$4 -> Avellaneda | F26: 1er tiempo suplementario | G26: =+'Reporte a FCCF'!$B$9 -> 1 | H26: =+'Reporte a FCCF'!$C$9 -> LUCIA COSTA | I26: =+'Reporte a FCCF'!T9 -> 0 | J26: =+'Reporte a FCCF'!U9 -> 0 | K26: =+'Reporte a FCCF'!V9 -> 0 | L26: =+'Reporte a FCCF'!W9 -> 0 | M26: =+'Reporte a FCCF'!X9 -> 0 | N26: =+'Reporte a FCCF'!Y9 -> 0 | O26: =+'Reporte a FCCF'!Z9 -> 0 | P26: =+'Reporte a FCCF'!AA9 -> 0
A27: =+'Reporte a FCCF'!$I$4 -> Primera A | B27: =+'Reporte a FCCF'!$I$2 -> Apertura 2026 | C27: =+'Reporte a FCCF'!$Q$2 -> 0 | D27: =+'Reporte a FCCF'!$C$2 -> Vélez | E27: =+'Reporte a FCCF'!$C$4 -> Avellaneda | F27: 1er tiempo suplementario | G27: =+'Reporte a FCCF'!$B$10 -> 5 | H27: =+'Reporte a FCCF'!$C$10 -> MARIELA ELIAS | I27: =+'Reporte a FCCF'!T10 -> 0 | J27: =+'Reporte a FCCF'!U10 -> 0 | K27: =+'Reporte a FCCF'!V10 -> 0 | L27: =+'Reporte a FCCF'!W10 -> 0 | M27: =+'Reporte a FCCF'!X10 -> 0 | N27: =+'Reporte a FCCF'!Y10 -> 0 | O27: =+'Reporte a FCCF'!Z10 -> 0 | P27: =+'Reporte a FCCF'!AA10 -> 0
A28: =+'Reporte a FCCF'!$I$4 -> Primera A | B28: =+'Reporte a FCCF'!$I$2 -> Apertura 2026 | C28: =+'Reporte a FCCF'!$Q$2 -> 0 | D28: =+'Reporte a FCCF'!$C$2 -> Vélez | E28: =+'Reporte a FCCF'!$C$4 -> Avellaneda | F28: 1er tiempo suplementario | G28: =+'Reporte a FCCF'!$B$11 -> 6 | H28: =+'Reporte a FCCF'!$C$11 -> MALENA ZUCCARINO | I28: =+'Reporte a FCCF'!T11 -> 0 | J28: =+'Reporte a FCCF'!U11 -> 0 | K28: =+'Reporte a FCCF'!V11 -> 0 | L28: =+'Reporte a FCCF'!W11 -> 0 | M28: =+'Reporte a FCCF'!X11 -> 0 | N28: =+'Reporte a FCCF'!Y11 -> 0 | O28: =+'Reporte a FCCF'!Z11 -> 0 | P28: =+'Reporte a FCCF'!AA11 -> 0
A29: =+'Reporte a FCCF'!$I$4 -> Primera A | B29: =+'Reporte a FCCF'!$I$2 -> Apertura 2026 | C29: =+'Reporte a FCCF'!$Q$2 -> 0 | D29: =+'Reporte a FCCF'!$C$2 -> Vélez | E29: =+'Reporte a FCCF'!$C$4 -> Avellaneda | F29: 1er tiempo suplementario | G29: =+'Reporte a FCCF'!$B$12 -> 7 | H29: =+'Reporte a FCCF'!$C$12 -> JIMENA GARCIA | I29: =+'Reporte a FCCF'!T12 -> 0 | J29: =+'Reporte a FCCF'!U12 -> 0 | K29: =+'Reporte a FCCF'!V12 -> 0 | L29: =+'Reporte a FCCF'!W12 -> 0 | M29: =+'Reporte a FCCF'!X12 -> 0 | N29: =+'Reporte a FCCF'!Y12 -> 0 | O29: =+'Reporte a FCCF'!Z12 -> 0 | P29: =+'Reporte a FCCF'!AA12 -> 0
A30: =+'Reporte a FCCF'!$I$4 -> Primera A | B30: =+'Reporte a FCCF'!$I$2 -> Apertura 2026 | C30: =+'Reporte a FCCF'!$Q$2 -> 0 | D30: =+'Reporte a FCCF'!$C$2 -> Vélez | E30: =+'Reporte a FCCF'!$C$4 -> Avellaneda | F30: 1er tiempo suplementario | G30: =+'Reporte a FCCF'!$B$13 -> 8 | H30: =+'Reporte a FCCF'!$C$13 -> SOFIA NAÓN | I30: =+'Reporte a FCCF'!T13 -> 0 | J30: =+'Reporte a FCCF'!U13 -> 0 | K30: =+'Reporte a FCCF'!V13 -> 0 | L30: =+'Reporte a FCCF'!W13 -> 0 | M30: =+'Reporte a FCCF'!X13 -> 0 | N30: =+'Reporte a FCCF'!Y13 -> 0 | O30: =+'Reporte a FCCF'!Z13 -> 0 | P30: =+'Reporte a FCCF'!AA13 -> 0
A31: =+'Reporte a FCCF'!$I$4 -> Primera A | B31: =+'Reporte a FCCF'!$I$2 -> Apertura 2026 | C31: =+'Reporte a FCCF'!$Q$2 -> 0 | D31: =+'Reporte a FCCF'!$C$2 -> Vélez | E31: =+'Reporte a FCCF'!$C$4 -> Avellaneda | F31: 1er tiempo suplementario | G31: =+'Reporte a FCCF'!$B$14 -> 9 | H31: =+'Reporte a FCCF'!$C$14 -> VICTORIA FONTAN | I31: =+'Reporte a FCCF'!T14 -> 0 | J31: =+'Reporte a FCCF'!U14 -> 0 | K31: =+'Reporte a FCCF'!V14 -> 0 | L31: =+'Reporte a FCCF'!W14 -> 0 | M31: =+'Reporte a FCCF'!X14 -> 0 | N31: =+'Reporte a FCCF'!Y14 -> 0 | O31: =+'Reporte a FCCF'!Z14 -> 0 | P31: =+'Reporte a FCCF'!AA14 -> 0
A32: =+'Reporte a FCCF'!$I$4 -> Primera A | B32: =+'Reporte a FCCF'!$I$2 -> Apertura 2026 | C32: =+'Reporte a FCCF'!$Q$2 -> 0 | D32: =+'Reporte a FCCF'!$C$2 -> Vélez | E32: =+'Reporte a FCCF'!$C$4 -> Avellaneda | F32: 1er tiempo suplementario | G32: =+'Reporte a FCCF'!$B$15 -> 10 | H32: =+'Reporte a FCCF'!$C$15 -> ZAHIRA HERRERA | I32: =+'Reporte a FCCF'!T15 -> 0 | J32: =+'Reporte a FCCF'!U15 -> 0 | K32: =+'Reporte a FCCF'!V15 -> 0 | L32: =+'Reporte a FCCF'!W15 -> 0 | M32: =+'Reporte a FCCF'!X15 -> 0 | N32: =+'Reporte a FCCF'!Y15 -> 0 | O32: =+'Reporte a FCCF'!Z15 -> 0 | P32: =+'Reporte a FCCF'!AA15 -> 0
A33: =+'Reporte a FCCF'!$I$4 -> Primera A | B33: =+'Reporte a FCCF'!$I$2 -> Apertura 2026 | C33: =+'Reporte a FCCF'!$Q$2 -> 0 | D33: =+'Reporte a FCCF'!$C$2 -> Vélez | E33: =+'Reporte a FCCF'!$C$4 -> Avellaneda | F33: 1er tiempo suplementario | G33: =+'Reporte a FCCF'!$B$16 -> 11 | H33: =+'Reporte a FCCF'!$C$16 -> LUCILA GRANATELLI | I33: =+'Reporte a FCCF'!T16 -> 0 | J33: =+'Reporte a FCCF'!U16 -> 0 | K33: =+'Reporte a FCCF'!V16 -> 0 | L33: =+'Reporte a FCCF'!W16 -> 0 | M33: =+'Reporte a FCCF'!X16 -> 0 | N33: =+'Reporte a FCCF'!Y16 -> 0 | O33: =+'Reporte a FCCF'!Z16 -> 0 | P33: =+'Reporte a FCCF'!AA16 -> 0
A34: =+'Reporte a FCCF'!$I$4 -> Primera A | B34: =+'Reporte a FCCF'!$I$2 -> Apertura 2026 | C34: =+'Reporte a FCCF'!$Q$2 -> 0 | D34: =+'Reporte a FCCF'!$C$2 -> Vélez | E34: =+'Reporte a FCCF'!$C$4 -> Avellaneda | F34: 1er tiempo suplementario | G34: =+'Reporte a FCCF'!$B$17 -> 12 | H34: =+'Reporte a FCCF'!$C$17 -> MARIA PAZ GOMEZ | I34: =+'Reporte a FCCF'!T17 -> 0 | J34: =+'Reporte a FCCF'!U17 -> 0 | K34: =+'Reporte a FCCF'!V17 -> 0 | L34: =+'Reporte a FCCF'!W17 -> 0 | M34: =+'Reporte a FCCF'!X17 -> 0 | N34: =+'Reporte a FCCF'!Y17 -> 0 | O34: =+'Reporte a FCCF'!Z17 -> 0 | P34: =+'Reporte a FCCF'!AA17 -> 0
A35: =+'Reporte a FCCF'!$I$4 -> Primera A | B35: =+'Reporte a FCCF'!$I$2 -> Apertura 2026 | C35: =+'Reporte a FCCF'!$Q$2 -> 0 | D35: =+'Reporte a FCCF'!$C$2 -> Vélez | E35: =+'Reporte a FCCF'!$C$4 -> Avellaneda | F35: 1er tiempo suplementario | G35: =+'Reporte a FCCF'!$B$18 -> 14 | H35: =+'Reporte a FCCF'!$C$18 -> LUCIANA BRINGAS | I35: =+'Reporte a FCCF'!T18 -> 0 | J35: =+'Reporte a FCCF'!U18 -> 0 | K35: =+'Reporte a FCCF'!V18 -> 0 | L35: =+'Reporte a FCCF'!W18 -> 0 | M35: =+'Reporte a FCCF'!X18 -> 0 | N35: =+'Reporte a FCCF'!Y18 -> 0 | O35: =+'Reporte a FCCF'!Z18 -> 0 | P35: =+'Reporte a FCCF'!AA18 -> 0
A36: =+'Reporte a FCCF'!$I$4 -> Primera A | B36: =+'Reporte a FCCF'!$I$2 -> Apertura 2026 | C36: =+'Reporte a FCCF'!$Q$2 -> 0 | D36: =+'Reporte a FCCF'!$C$2 -> Vélez | E36: =+'Reporte a FCCF'!$C$4 -> Avellaneda | F36: 1er tiempo suplementario | G36: =+'Reporte a FCCF'!$B$19 -> 15 | H36: =+'Reporte a FCCF'!$C$19 -> CANDELA THIM | I36: =+'Reporte a FCCF'!T19 -> 0 | J36: =+'Reporte a FCCF'!U19 -> 0 | K36: =+'Reporte a FCCF'!V19 -> 0 | L36: =+'Reporte a FCCF'!W19 -> 0 | M36: =+'Reporte a FCCF'!X19 -> 0 | N36: =+'Reporte a FCCF'!Y19 -> 0 | O36: =+'Reporte a FCCF'!Z19 -> 0 | P36: =+'Reporte a FCCF'!AA19 -> 0
A37: =+'Reporte a FCCF'!$I$4 -> Primera A | B37: =+'Reporte a FCCF'!$I$2 -> Apertura 2026 | C37: =+'Reporte a FCCF'!$Q$2 -> 0 | D37: =+'Reporte a FCCF'!$C$2 -> Vélez | E37: =+'Reporte a FCCF'!$C$4 -> Avellaneda | F37: 1er tiempo suplementario | G37: =+'Reporte a FCCF'!$B$20 -> 0 | H37: =+'Reporte a FCCF'!$C$20 -> 0 | I37: =+'Reporte a FCCF'!T20 -> 0 | J37: =+'Reporte a FCCF'!U20 -> 0 | K37: =+'Reporte a FCCF'!V20 -> 0 | L37: =+'Reporte a FCCF'!W20 -> 0 | M37: =+'Reporte a FCCF'!X20 -> 0 | N37: =+'Reporte a FCCF'!Y20 -> 0 | O37: =+'Reporte a FCCF'!Z20 -> 0 | P37: =+'Reporte a FCCF'!AA20 -> 0
A38: =+'Reporte a FCCF'!$I$4 -> Primera A | B38: =+'Reporte a FCCF'!$I$2 -> Apertura 2026 | C38: =+'Reporte a FCCF'!$Q$2 -> 0 | D38: =+'Reporte a FCCF'!$C$2 -> Vélez | E38: =+'Reporte a FCCF'!$C$4 -> Avellaneda | F38: 2do tiempo suplementario | G38: =+'Reporte a FCCF'!$B$9 -> 1 | H38: =+'Reporte a FCCF'!$C$9 -> LUCIA COSTA | I38: =+'Reporte a FCCF'!AB9 -> 0 | J38: =+'Reporte a FCCF'!AC9 -> 0 | K38: =+'Reporte a FCCF'!AD9 -> 0 | L38: =+'Reporte a FCCF'!AE9 -> 0 | M38: =+'Reporte a FCCF'!AF9 -> 0 | N38: =+'Reporte a FCCF'!AG9 -> 0 | O38: =+'Reporte a FCCF'!AH9 -> 0 | P38: =+'Reporte a FCCF'!AI9 -> 0
A39: =+'Reporte a FCCF'!$I$4 -> Primera A | B39: =+'Reporte a FCCF'!$I$2 -> Apertura 2026 | C39: =+'Reporte a FCCF'!$Q$2 -> 0 | D39: =+'Reporte a FCCF'!$C$2 -> Vélez | E39: =+'Reporte a FCCF'!$C$4 -> Avellaneda | F39: 2do tiempo suplementario | G39: =+'Reporte a FCCF'!$B$10 -> 5 | H39: =+'Reporte a FCCF'!$C$10 -> MARIELA ELIAS | I39: =+'Reporte a FCCF'!AB10 -> 0 | J39: =+'Reporte a FCCF'!AC10 -> 0 | K39: =+'Reporte a FCCF'!AD10 -> 0 | L39: =+'Reporte a FCCF'!AE10 -> 0 | M39: =+'Reporte a FCCF'!AF10 -> 0 | N39: =+'Reporte a FCCF'!AG10 -> 0 | O39: =+'Reporte a FCCF'!AH10 -> 0 | P39: =+'Reporte a FCCF'!AI10 -> 0
A40: =+'Reporte a FCCF'!$I$4 -> Primera A | B40: =+'Reporte a FCCF'!$I$2 -> Apertura 2026 | C40: =+'Reporte a FCCF'!$Q$2 -> 0 | D40: =+'Reporte a FCCF'!$C$2 -> Vélez | E40: =+'Reporte a FCCF'!$C$4 -> Avellaneda | F40: 2do tiempo suplementario | G40: =+'Reporte a FCCF'!$B$11 -> 6 | H40: =+'Reporte a FCCF'!$C$11 -> MALENA ZUCCARINO | I40: =+'Reporte a FCCF'!AB11 -> 0 | J40: =+'Reporte a FCCF'!AC11 -> 0 | K40: =+'Reporte a FCCF'!AD11 -> 0 | L40: =+'Reporte a FCCF'!AE11 -> 0 | M40: =+'Reporte a FCCF'!AF11 -> 0 | N40: =+'Reporte a FCCF'!AG11 -> 0 | O40: =+'Reporte a FCCF'!AH11 -> 0 | P40: =+'Reporte a FCCF'!AI11 -> 0
...

Sheet Para importar
B2: Club: | C2: =+'Reporte a FCCF'!C2 -> Vélez | G2: Torneo: | I2: =+'Reporte a FCCF'!I2 -> Apertura 2026 | P2: Fecha: | Q2: =+'Reporte a FCCF'!Q2 -> 0
B4: Rival: | C4: =+'Reporte a FCCF'!C4 -> Avellaneda | G4: Categoría: | I4: =+'Reporte a FCCF'!I4 -> Primera A
D6: 1er tiempo | L6: 2do tiempo | T6: 1er tiempo suplementario | AB6: 2do tiempo suplementario | AJ6: TOTAL
B7: # | C7: Nombre | D7: Lanza mientos | E7: Goles | G7: Rebotes | I7: Recu peros | J7: Pér didas | K7: Faltas | L7: Lanza mientos | M7: Goles | O7: Rebotes | Q7: Recu peros | R7: Pér didas | S7: Faltas | T7: Lanza mientos | U7: Goles | W7: Rebotes | Y7: Recu peros | Z7: Pér didas | AA7: Faltas | AB7: Lanza mientos | AC7: Goles | AE7: Rebotes | AG7: Recu peros | AH7: Pér didas | AI7: Faltas | AJ7: Lanza mientos | AK7: Goles | AM7: Rebotes | AO7: Recuperos | AP7: Pérdidas | AQ7: Faltas
E8: Dobles | F8: Triples | G8: Ofens | H8: Defens | M8: Dobles | N8: Triples | O8: Ofens | P8: Defens | U8: Dobles | V8: Triples | W8: Ofens | X8: Defens | AC8: Dobles | AD8: Triples | AE8: Ofens | AF8: Defens | AK8: Dobles | AL8: Triples | AM8: Ofensivos | AN8: Defensivos
B9: =+'Reporte a FCCF'!B9 -> 1 | C9: =+'Reporte a FCCF'!C9 -> LUCIA COSTA | D9: =+'Reporte a FCCF'!D9 -> 4 | E9: =+'Reporte a FCCF'!E9 -> 1 | F9: =+'Reporte a FCCF'!F9 -> 0 | G9: =+'Reporte a FCCF'!G9 -> 2 | H9: =+'Reporte a FCCF'!H9 -> 1 | I9: =+'Reporte a FCCF'!I9 -> 0 | ... AI9: =+'Reporte a FCCF'!AI9 -> 0 | AJ9: =+D9+L9+T9+AB9 -> 4 | AK9: =+E9+M9+U9+AC9 -> 1 | AL9: =+F9+N9+V9+AD9 -> 0 | AM9: =+G9+O9+W9+AE9 -> 3 | AN9: =+H9+P9+X9+AF9 -> 1 | AO9: =+I9+Q9+Y9+AG9 -> 0 | AP9: =+J9+R9+Z9+AH9 -> 3 | AQ9: =+K9+S9+AA9+AI9 -> 6
B10: =+'Reporte a FCCF'!B10 -> 5 | C10: =+'Reporte a FCCF'!C10 -> MARIELA ELIAS | D10: =+'Reporte a FCCF'!D10 -> 0 | E10: =+'Reporte a FCCF'!E10 -> 0 | F10: =+'Reporte a FCCF'!F10 -> 0 | G10: =+'Reporte a FCCF'!G10 -> 0 | H10: =+'Reporte a FCCF'!H10 -> 0 | I10: =+'Reporte a FCCF'!I10 -> 0 | ... AI10: =+'Reporte a FCCF'!AI10 -> 0 | AJ10: =+D10+L10+T10+AB10 -> 1 | AK10: =+E10+M10+U10+AC10 -> 0 | AL10: =+F10+N10+V10+AD10 -> 0 | AM10: =+G10+O10+W10+AE10 -> 0 | AN10: =+H10+P10+X10+AF10 -> 3 | AO10: =+I10+Q10+Y10+AG10 -> 2 | AP10: =+J10+R10+Z10+AH10 -> 4 | AQ10: =+K10+S10+AA10+AI10 -> 5
B11: =+'Reporte a FCCF'!B11 -> 6 | C11: =+'Reporte a FCCF'!C11 -> MALENA ZUCCARINO | D11: =+'Reporte a FCCF'!D11 -> 0 | E11: =+'Reporte a FCCF'!E11 -> 0 | F11: =+'Reporte a FCCF'!F11 -> 0 | G11: =+'Reporte a FCCF'!G11 -> 0 | H11: =+'Reporte a FCCF'!H11 -> 0 | I11: =+'Reporte a FCCF'!I11 -> 0 | ... AI11: =+'Reporte a FCCF'!AI11 -> 0 | AJ11: =+D11+L11+T11+AB11 -> 4 | AK11: =+E11+M11+U11+AC11 -> 2 | AL11: =+F11+N11+V11+AD11 -> 0 | AM11: =+G11+O11+W11+AE11 -> 2 | AN11: =+H11+P11+X11+AF11 -> 1 | AO11: =+I11+Q11+Y11+AG11 -> 0 | AP11: =+J11+R11+Z11+AH11 -> 0 | AQ11: =+K11+S11+AA11+AI11 -> 3
B12: =+'Reporte a FCCF'!B12 -> 7 | C12: =+'Reporte a FCCF'!C12 -> JIMENA GARCIA | D12: =+'Reporte a FCCF'!D12 -> 11 | E12: =+'Reporte a FCCF'!E12 -> 5 | F12: =+'Reporte a FCCF'!F12 -> 0 | G12: =+'Reporte a FCCF'!G12 -> 0 | H12: =+'Reporte a FCCF'!H12 -> 0 | I12: =+'Reporte a FCCF'!I12 -> 1 | ... AI12: =+'Reporte a FCCF'!AI12 -> 0 | AJ12: =+D12+L12+T12+AB12 -> 20 | AK12: =+E12+M12+U12+AC12 -> 9 | AL12: =+F12+N12+V12+AD12 -> 0 | AM12: =+G12+O12+W12+AE12 -> 1 | AN12: =+H12+P12+X12+AF12 -> 0 | AO12: =+I12+Q12+Y12+AG12 -> 1 | AP12: =+J12+R12+Z12+AH12 -> 3 | AQ12: =+K12+S12+AA12+AI12 -> 3
B13: =+'Reporte a FCCF'!B13 -> 8 | C13: =+'Reporte a FCCF'!C13 -> SOFIA NAÓN | D13: =+'Reporte a FCCF'!D13 -> 6 | E13: =+'Reporte a FCCF'!E13 -> 3 | F13: =+'Reporte a FCCF'!F13 -> 0 | G13: =+'Reporte a FCCF'!G13 -> 0 | H13: =+'Reporte a FCCF'!H13 -> 3 | I13: =+'Reporte a FCCF'!I13 -> 0 | ... AI13: =+'Reporte a FCCF'!AI13 -> 0 | AJ13: =+D13+L13+T13+AB13 -> 14 | AK13: =+E13+M13+U13+AC13 -> 8 | AL13: =+F13+N13+V13+AD13 -> 0 | AM13: =+G13+O13+W13+AE13 -> 2 | AN13: =+H13+P13+X13+AF13 -> 3 | AO13: =+I13+Q13+Y13+AG13 -> 1 | AP13: =+J13+R13+Z13+AH13 -> 3 | AQ13: =+K13+S13+AA13+AI13 -> 5
B14: =+'Reporte a FCCF'!B14 -> 9 | C14: =+'Reporte a FCCF'!C14 -> VICTORIA FONTAN | D14: =+'Reporte a FCCF'!D14 -> 1 | E14: =+'Reporte a FCCF'!E14 -> 0 | F14: =+'Reporte a FCCF'!F14 -> 0 | G14: =+'Reporte a FCCF'!G14 -> 0 | H14: =+'Reporte a FCCF'!H14 -> 7 | I14: =+'Reporte a FCCF'!I14 -> 2 | ... AI14: =+'Reporte a FCCF'!AI14 -> 0 | AJ14: =+D14+L14+T14+AB14 -> 5 | AK14: =+E14+M14+U14+AC14 -> 2 | AL14: =+F14+N14+V14+AD14 -> 0 | AM14: =+G14+O14+W14+AE14 -> 0 | AN14: =+H14+P14+X14+AF14 -> 17 | AO14: =+I14+Q14+Y14+AG14 -> 2 | AP14: =+J14+R14+Z14+AH14 -> 1 | AQ14: =+K14+S14+AA14+AI14 -> 4
B15: =+'Reporte a FCCF'!B15 -> 10 | C15: =+'Reporte a FCCF'!C15 -> ZAHIRA HERRERA | D15: =+'Reporte a FCCF'!D15 -> 0 | E15: =+'Reporte a FCCF'!E15 -> 0 | F15: =+'Reporte a FCCF'!F15 -> 0 | G15: =+'Reporte a FCCF'!G15 -> 0 | H15: =+'Reporte a FCCF'!H15 -> 1 | I15: =+'Reporte a FCCF'!I15 -> 0 | ... AI15: =+'Reporte a FCCF'!AI15 -> 0 | AJ15: =+D15+L15+T15+AB15 -> 0 | AK15: =+E15+M15+U15+AC15 -> 0 | AL15: =+F15+N15+V15+AD15 -> 0 | AM15: =+G15+O15+W15+AE15 -> 0 | AN15: =+H15+P15+X15+AF15 -> 1 | AO15: =+I15+Q15+Y15+AG15 -> 1 | AP15: =+J15+R15+Z15+AH15 -> 1 | AQ15: =+K15+S15+AA15+AI15 -> 6
B16: =+'Reporte a FCCF'!B16 -> 11 | C16: =+'Reporte a FCCF'!C16 -> LUCILA GRANATELLI | D16: =+'Reporte a FCCF'!D16 -> 9 | E16: =+'Reporte a FCCF'!E16 -> 6 | F16: =+'Reporte a FCCF'!F16 -> 0 | G16: =+'Reporte a FCCF'!G16 -> 1 | H16: =+'Reporte a FCCF'!H16 -> 1 | I16: =+'Reporte a FCCF'!I16 -> 0 | ... AI16: =+'Reporte a FCCF'!AI16 -> 0 | AJ16: =+D16+L16+T16+AB16 -> 16 | AK16: =+E16+M16+U16+AC16 -> 11 | AL16: =+F16+N16+V16+AD16 -> 0 | AM16: =+G16+O16+W16+AE16 -> 3 | AN16: =+H16+P16+X16+AF16 -> 1 | AO16: =+I16+Q16+Y16+AG16 -> 0 | AP16: =+J16+R16+Z16+AH16 -> 1 | AQ16: =+K16+S16+AA16+AI16 -> 4
B17: =+'Reporte a FCCF'!B17 -> 12 | C17: =+'Reporte a FCCF'!C17 -> MARIA PAZ GOMEZ | D17: =+'Reporte a FCCF'!D17 -> 1 | E17: =+'Reporte a FCCF'!E17 -> 0 | F17: =+'Reporte a FCCF'!F17 -> 0 | G17: =+'Reporte a FCCF'!G17 -> 0 | H17: =+'Reporte a FCCF'!H17 -> 0 | I17: =+'Reporte a FCCF'!I17 -> 1 | ... AI17: =+'Reporte a FCCF'!AI17 -> 0 | AJ17: =+D17+L17+T17+AB17 -> 11 | AK17: =+E17+M17+U17+AC17 -> 5 | AL17: =+F17+N17+V17+AD17 -> 2 | AM17: =+G17+O17+W17+AE17 -> 1 | AN17: =+H17+P17+X17+AF17 -> 1 | AO17: =+I17+Q17+Y17+AG17 -> 1 | AP17: =+J17+R17+Z17+AH17 -> 1 | AQ17: =+K17+S17+AA17+AI17 -> 1
B18: =+'Reporte a FCCF'!B18 -> 14 | C18: =+'Reporte a FCCF'!C18 -> LUCIANA BRINGAS | D18: =+'Reporte a FCCF'!D18 -> 0 | E18: =+'Reporte a FCCF'!E18 -> 0 | F18: =+'Reporte a FCCF'!F18 -> 0 | G18: =+'Reporte a FCCF'!G18 -> 0 | H18: =+'Reporte a FCCF'!H18 -> 1 | I18: =+'Reporte a FCCF'!I18 -> 0 | ... AI18: =+'Reporte a FCCF'!AI18 -> 0 | AJ18: =+D18+L18+T18+AB18 -> 1 | AK18: =+E18+M18+U18+AC18 -> 0 | AL18: =+F18+N18+V18+AD18 -> 0 | AM18: =+G18+O18+W18+AE18 -> 0 | AN18: =+H18+P18+X18+AF18 -> 2 | AO18: =+I18+Q18+Y18+AG18 -> 1 | AP18: =+J18+R18+Z18+AH18 -> 0 | AQ18: =+K18+S18+AA18+AI18 -> 5
B19: =+'Reporte a FCCF'!B19 -> 15 | C19: =+'Reporte a FCCF'!C19 -> CANDELA THIM | D19: =+'Reporte a FCCF'!D19 -> 4 | E19: =+'Reporte a FCCF'!E19 -> 1 | F19: =+'Reporte a FCCF'!F19 -> 0 | G19: =+'Reporte a FCCF'!G19 -> 1 | H19: =+'Reporte a FCCF'!H19 -> 0 | I19: =+'Reporte a FCCF'!I19 -> 0 | ... AI19: =+'Reporte a FCCF'!AI19 -> 0 | AJ19: =+D19+L19+T19+AB19 -> 4 | AK19: =+E19+M19+U19+AC19 -> 1 | AL19: =+F19+N19+V19+AD19 -> 0 | AM19: =+G19+O19+W19+AE19 -> 1 | AN19: =+H19+P19+X19+AF19 -> 0 | AO19: =+I19+Q19+Y19+AG19 -> 0 | AP19: =+J19+R19+Z19+AH19 -> 1 | AQ19: =+K19+S19+AA19+AI19 -> 2
B20: =+'Reporte a FCCF'!B20 -> 0 | C20: =+'Reporte a FCCF'!C20 -> 0 | D20: =+'Reporte a FCCF'!D20 -> 0 | E20: =+'Reporte a FCCF'!E20 -> 0 | F20: =+'Reporte a FCCF'!F20 -> 0 | G20: =+'Reporte a FCCF'!G20 -> 0 | H20: =+'Reporte a FCCF'!H20 -> 0 | I20: =+'Reporte a FCCF'!I20 -> 0 | ... AI20: =+'Reporte a FCCF'!AI20 -> 0 | AJ20: =+D20+L20+T20+AB20 -> 0 | AK20: =+E20+M20+U20+AC20 -> 0 | AL20: =+F20+N20+V20+AD20 -> 0 | AM20: =+G20+O20+W20+AE20 -> 0 | AN20: =+H20+P20+X20+AF20 -> 0 | AO20: =+I20+Q20+Y20+AG20 -> 0 | AP20: =+J20+R20+Z20+AH20 -> 0 | AQ20: =+K20+S20+AA20+AI20 -> 0
B22: TOTAL | D22: =SUM(D9:D20) -> 36 | E22: =SUM(E9:E20) -> 16 | F22: =SUM(F9:F20) -> 0 | G22: =SUM(G9:G20) -> 4 | H22: =SUM(H9:H20) -> 14 | I22: =SUM(I9:I20) -> 4 | J22: =SUM(J9:J20) -> 10 | K22: =SUM(K9:K20) -> 18 | ... AQ22: =SUM(AQ9:AQ20) -> 44
B24: Estadísticas | Reporte a FCCF v2

Sheet Aux
A1: Masculino | C1: APV | E1: Apertura 2024 | G1: 45372
A2: Primera A | C2: APV masc A | E2: Clausura 2024
C3: APV masc B | E3: Apertura 2025
C4: Avellaneda | E4: Clausura 2025
C5: Ballester | E5: Apertura 2026
C6: CEF La Plata | E6: Clausura 2026
C7: Ciudad | E7: Apertura 2027
C8: GEVP | E8: Clausura 2027
C9: Hacoaj | E9: Apertura 2028
C10: San Martín | E10: Clausura 2028
C11: SITAS | E11: Apertura 2029
C12: Social Parque | E12: Clausura 2029
C13: Vélez | E13: Apertura 2030
E14: Clausura 2030
